<?xml version="1.0" ?>

<robot name="irb1660_6_155" xmlns:xacro="http://ros.org/wiki/xacro">
 
  <!-- robot link list -->
  <link name="base_link">
    <visual>
      <origin rpy="0 0 0" xyz="0 0 0"/>
      <geometry>
        <mesh filename="package://abb_irb1660_support/meshes/base_link.stl"/>
      </geometry>
      <material name="abb_orange">
        <color rgba="1 0.43 0 1"/>
      </material>
    </visual>
    <collision>
      <geometry>
        <mesh filename="package://abb_irb1660_support/meshes/base_link.stl"/>
      </geometry>
      <material name="yellow">
        <color rgba="0 1 1 1"/>
      </material>
    </collision>
  </link>
  <link name="link_1">
    <visual>
      <origin rpy="0 0 0" xyz="0 0 0"/>
      <geometry>
        <mesh filename="package://abb_irb1660_support/meshes/link_1.stl"/>
      </geometry>
      <material name="abb_orange"/>
    </visual>
    <collision>
      <origin rpy="0 0 0" xyz="0 0 0"/>
      <geometry>
        <mesh filename="package://abb_irb1660_support/meshes/link_1.stl"/>
      </geometry>
      <material name="yellow"/>
    </collision>
  </link>
  <link name="link_2">
    <visual>
      <origin rpy="0 0 0" xyz="0 0 0"/>
      <geometry>
        <mesh filename="package://abb_irb1660_support/meshes/link_2.stl"/>
      </geometry>
      <material name="abb_orange"/>
    </visual>
    <collision>
      <origin rpy="0 0 0" xyz="0 0 0"/>
      <geometry>
        <mesh filename="package://abb_irb1660_support/meshes/link_2.stl"/>
      </geometry>
      <material name="yellow"/>
    </collision>
  </link>
  <link name="link_3">
    <visual>
      <origin rpy="0 0 0" xyz="0 0 0"/>
      <geometry>
        <mesh filename="package://abb_irb1660_support/meshes/link_3.stl"/>
      </geometry>
      <material name="abb_orange"/>
    </visual>
    <collision>
      <origin rpy="0 0 0" xyz="0 0 0"/>
      <geometry>
        <mesh filename="package://abb_irb1660_support/meshes/link_3.stl"/>
      </geometry>
      <material name="yellow"/>
    </collision>
  </link>
  <link name="link_4">
    <visual>
      <origin rpy="0 0 0" xyz="0 0 0"/>
      <geometry>
        <mesh filename="package://abb_irb1660_support/meshes/link_4.stl"/>
      </geometry>
      <material name="abb_orange"/>
    </visual>
    <collision>
      <origin rpy="0 0 0" xyz="0 0 0"/>
      <geometry>
        <mesh filename="package://abb_irb1660_support/meshes/link_4.stl"/>
      </geometry>
      <material name="yellow"/>
    </collision>
  </link>
  <link name="link_5">
    <visual>
      <origin rpy="0 0 0" xyz="0 0 0"/>
      <geometry>
        <mesh filename="package://abb_irb1660_support/meshes/link_5.stl"/>
      </geometry>
      <material name="abb_orange"/>
    </visual>
    <collision>
      <origin rpy="0 0 0" xyz="0 0 0"/>
      <geometry>
        <mesh filename="package://abb_irb1660_support/meshes/link_5.stl"/>
      </geometry>
      <material name="yellow"/>
    </collision>
  </link>
  <link name="link_6">
    <visual>
      <origin rpy="0 0 0" xyz="0 0 0"/>
      <geometry>
        <mesh filename="package://abb_irb1660_support/meshes/link_6.stl"/>
      </geometry>
      <material name="abb_orange"/>
    </visual>
    <collision>
      <origin rpy="0 0 0" xyz="0 0 0"/>
      <geometry>
        <mesh filename="package://abb_irb1660_support/meshes/link_6.stl"/>
      </geometry>
      <material name="yellow"/>
    </collision>
  </link>

  <!-- tool link list -->
  <link name="tool0">
  <visual>
      <origin rpy="0 0 0" xyz="0 0 0"/>
      <geometry>
        <mesh filename="package://abb_irb1660_support/meshes/tools/tool_sks_FP8i-L.stl"/>
      </geometry>
      <material name="abb_orange"/>
    </visual>
    <collision>
      <origin rpy="0 0 0" xyz="0 0 0"/>
      <geometry>
        <mesh filename="package://abb_irb1660_support/meshes/tools/tool_sks_FP8i-L.stl"/>
      </geometry>
      <material name="yellow"/>
    </collision>
  </link>

  <!-- camera link list -->
  <link name="camera_link">
  <visual>
    <origin rpy="0 0 0" xyz="0 0 0"/>
    <geometry>
      <box size="0.05 0.05 0.05"/>
    </geometry>
    </visual>
    <material name="Cyan">
      <color rgba="0 1.0 0 1.0"/>
    </material>
  </link>
  <link name="camera_optical_frame">
  <visual>
      <origin rpy="0 0 0" xyz="0.0 0.0 0"/>
      <geometry>
        <sphere radius="0.005"/>
      </geometry>
    </visual>
  </link>
  <link name="led_link">
  <visual>
      <origin rpy="0 0 0" xyz="0 0 -0.057"/>
      <geometry>
        <sphere radius="0.01"/>
      </geometry>
    </visual>
  </link>
  <!-- end of link list -->

  <!-- robot joint list -->
  <joint name="joint_1" type="revolute">
    <origin rpy="0 0 0" xyz="0 0 0.124"/>
    <parent link="base_link"/>
    <child link="link_1"/>
    <axis xyz="0 0 1"/>
    <limit effort="0" lower="-3.14159" upper="3.14159" velocity="3.14159"/>
  </joint>
  <joint name="joint_2" type="revolute">
    <origin rpy="0 0 0" xyz="0.15 -0.107 0.3625"/>
    <parent link="link_1"/>
    <child link="link_2"/>
    <axis xyz="0 1 0"/>
    <limit effort="0" lower="-1.5708" upper="2.61799" velocity="3.14159"/>
  </joint>
  <joint name="joint_3" type="revolute">
    <origin rpy="0 0 0" xyz="0 0 0.7"/>
    <parent link="link_2"/>
    <child link="link_3"/>
    <axis xyz="0 1 0"/>
    <limit effort="0" lower="-4.15388" upper="1.37881" velocity="3.14159"/>
  </joint>
  <joint name="joint_4" type="revolute">
    <origin rpy="0 0 0" xyz="0.128 0.107 0.108"/>
    <parent link="link_3"/>
    <child link="link_4"/>
    <axis xyz="1 0 0"/>
    <limit effort="0" lower="-3.05433" upper="3.05433" velocity="5.58505"/>
  </joint>
  <joint name="joint_5" type="revolute">
    <origin rpy="0 0 0" xyz="0.55 0 0"/>
    <parent link="link_4"/>
    <child link="link_5"/>
    <axis xyz="0 1 0"/>
    <limit effort="0" lower="-2.0944" upper="2.0944" velocity="6.28319"/>
  </joint>
  <joint name="joint_6" type="revolute">
    <origin rpy="0.0 0 0" xyz="0.135 0 0"/>
    <parent link="link_5"/>
    <child link="link_6"/>
    <axis xyz="1 0 0"/>
    <limit effort="0" lower="-6.98132" upper="6.98132" velocity="8.72665"/>
  </joint>

  <!-- tool joint list -->
  <joint name="joint_6-tool0" type="fixed">
    <parent link="link_6"/>
    <child link="tool0"/>
    <origin rpy="0 0 0" xyz="0 0 0"/>
  </joint>
  
  
  <!-- camera joint list -->
  <joint name="camera_joint" type="fixed">
    <origin rpy="0 0 -2.7488909" xyz="3.02 0.50 0.50"/>
    <parent link="base_link" />
    <child link="camera_link" />
  </joint>
  <joint name="camera_optical_joint" type="fixed">
    <origin rpy="0 0 0" xyz="0.025 0 0"/>
    <parent link="camera_link" />
    <child link="camera_optical_frame" />
  </joint>
  <joint name="led_joint" type="fixed">
    <origin rpy="0 0 0" xyz="0.463 0.0 -0.120"/>
    <parent link="tool0" />
    <child link="led_link" />
  </joint>
  <!-- end of joint list -->


  <!-- object placement -->
  <!-- object link list -->
  <link name="front_of_cel_link"/>

  <link name="external_axis_object">
    <visual>
      <origin rpy="0 0 0" xyz="0 0 0.525"/>
      <geometry>
        <box size="0.45 1.60 1.05"/>
      </geometry>
    </visual>
    <material name="Blue">
      <color rgba="0 0 1.0 1.0"/>
    </material>
    <collision>
      <origin rpy="0 0 0" xyz="0 0 0.525"/>
      <geometry>
        <box size="0.45 1.60 1.05"/>
      </geometry>
      <material name="Blue"/>
    </collision>
  </link>

   <link name="ground_object">
    <visual>
      <origin rpy="1.5708 0 0" xyz="0 -0.025 0"/>
      <geometry>
        <box size="4 0.05 3.25"/>
      </geometry>
    </visual>
    <material name="Cyan">
      <color rgba="0 255 0 0.3"/>
    </material>
    <collision>
      <origin rpy="1.5708  0 0" xyz="0 -0.025 0"/>
      <geometry>
        <box size="4 0.05 3.25"/>
      </geometry>
      <material name="Cyan">
      <color rgba="0 255 0 0.3"/>
    </material>
    </collision>
  </link>
   
  
  <link name="wall_back_object">
    <visual>
      <origin rpy="0 0 1.5708" xyz="0 0 1.25"/>
      <geometry>
        <box size="3.25 0.05 2.5"/>
      </geometry>
    </visual>
    <material name="Cyan">
      <color rgba="0 255 0 0.3"/>
    </material>
    <collision>
      <origin rpy="0 0 1.5708" xyz="0 0 1.25"/>
      <geometry>
        <box size="3.25 0.05 2.5"/>
      </geometry>
      <material name="Cyan">
      <color rgba="0 255 0 0.3"/>
    </material>
    </collision>
  </link>
  
  
  <link name="wall_left_object">
    <visual>
      <origin rpy="0 0 0" xyz="-2 0 1.25"/>
      <geometry>
        <box size="4 0.05 2.5"/>
      </geometry>
    </visual>
    <material name="Cyan">
      <color rgba="0 255 0 0.3"/>
    </material>
    <collision>
      <origin rpy="0 0 0" xyz="-2 0 1.25"/>
      <geometry>
        <box size="4 0.05 2.5"/>
      </geometry>
      <material name="Cyan">
      <color rgba="0 255 0 0.3"/>
    </material>
    </collision>
  </link>
  <link name="wall_right_object">
    <visual>
      <origin rpy="0 0 0" xyz="-2 0 1.25"/>
      <geometry>
        <box size="4 0.05 2.5"/>
      </geometry>
    </visual>
    <material name="Cyan">
      <color rgba="0 255 0 0.3"/>
    </material>
    <collision>
      <origin rpy="0 0 0" xyz="-2 0 1.25"/>
      <geometry>
        <box size="4 0.05 2.5"/>
      </geometry>
      <material name="Cyan">
      <color rgba="0 255 0 0.3"/>
    </material>
    </collision>
  </link>

  <!--object joint list -->
  <joint name="front_of_cel_joint" type="fixed">
    <origin rpy="0 0 0" xyz="2 0 -0.655"/>
    <parent link="base_link" />
    <child link="front_of_cel_link" />
  </joint>

  <joint name="external_axis_joint" type="fixed">
    <origin rpy="0 0 0" xyz="-0.75 0 0"/>
    <parent link="front_of_cel_link" />
    <child link="external_axis_object" />
  </joint>

  <joint name="ground_joint" type="fixed">
    <origin rpy="0 0 0" xyz="-2 0 0"/>
    <parent link="front_of_cel_link" />
    <child link="ground_object" />
  </joint>
  
  <joint name="front_to_back_wall_joint" type="fixed">
    <origin rpy="0 0 0" xyz="-4 0 0"/>
    <parent link="front_of_cel_link" />
    <child link="wall_back_object" />
  </joint>
  
  <joint name="front_to_left_wall_joint" type="fixed">
    <origin rpy="0 0 0" xyz="0 -1.625 0"/>
    <parent link="front_of_cel_link" />
    <child link="wall_left_object" />
  </joint>
  
  <joint name="front_to_right_wall_joint" type="fixed">
    <origin rpy="0 0 0" xyz="0 1.625 0"/>
    <parent link="front_of_cel_link" />
    <child link="wall_right_object" />
  </joint>
  <!--end of object placement -->
  
</robot>

