<?xml version="1.0" ?>
<!-- =================================================================================== -->
<!-- |    This document was autogenerated by xacro from /home/turtle/ros_robot_calib/src/robot_irb1660_id/urdf/robot_irb1600_macro.urdf | -->
<!-- |    EDITING THIS FILE BY HAND IS NOT RECOMMENDED, !!! LESS speed                                 | -->
<!-- =================================================================================== -->
<robot name="robot_irb1660_id" xmlns:xacro="http://ros.org/wiki/xacro">
  <!-- robot link list -->
  <link name="base_link">
    <visual>
      <origin rpy="0 0 0" xyz="0 0 0"/>
      <geometry>
        <mesh filename="package://robot_irb1660_id/meshes/base_link_bin.stl"/>
      </geometry>
      <material name="abb_orange">
        <color rgba="1 0.43 0 1"/>
      </material>
    </visual>
    <collision>
      <geometry>
        <mesh filename="package://robot_irb1660_id/meshes/base_link_bin.stl"/>
      </geometry>
      <material name="yellow">
        <color rgba="0 1 1 1"/>
      </material>
    </collision>
  </link>
  <link name="link_1">
    <visual>
      <origin rpy="0 0 0" xyz="0 0 0"/>
      <geometry>
        <mesh filename="package://robot_irb1660_id/meshes/link_1_bin_zeroed.stl"/>
      </geometry>
      <material name="abb_orange"/>
    </visual>
    <collision>
      <origin rpy="0 0 0" xyz="0 0 0"/>
      <geometry>
        <mesh filename="package://robot_irb1660_id/meshes/link_1_bin_zeroed.stl"/>
      </geometry>
      <material name="yellow"/>
    </collision>
  </link>
  <link name="link_2">
    <visual>
      <origin rpy="0 0 0" xyz="0 0 0"/>
      <geometry>
        <mesh filename="package://robot_irb1660_id/meshes/link_2_bin_zeroed.stl"/>
      </geometry>
      <material name="abb_orange"/>
    </visual>
    <collision>
      <origin rpy="0 0 0" xyz="0 0 0"/>
      <geometry>
        <mesh filename="package://robot_irb1660_id/meshes/link_2_bin_zeroed.stl"/>
      </geometry>
      <material name="yellow"/>
    </collision>
  </link>
  <link name="link_3">
    <visual>
      <origin rpy="0 0 0" xyz="0 0 0"/>
      <geometry>
        <mesh filename="package://robot_irb1660_id/meshes/link_3_bin_zeroed.stl"/>
      </geometry>
      <material name="abb_orange"/>
    </visual>
    <collision>
      <origin rpy="0 0 0" xyz="0 0 0"/>
      <geometry>
        <mesh filename="package://robot_irb1660_id/meshes/link_3_bin_zeroed.stl"/>
      </geometry>
      <material name="yellow"/>
    </collision>
  </link>
  <link name="link_4">
    <visual>
      <origin rpy="0 0 0" xyz="0 0 0"/>
      <geometry>
        <mesh filename="package://robot_irb1660_id/meshes/link_4_bin_zeroed.stl"/>
      </geometry>
      <material name="abb_orange"/>
    </visual>
    <collision>
      <origin rpy="0 0 0" xyz="0 0 0"/>
      <geometry>
        <mesh filename="package://robot_irb1660_id/meshes/link_4_bin_zeroed.stl"/>
      </geometry>
      <material name="yellow"/>
    </collision>
  </link>
  <link name="link_5">
    <visual>
      <origin rpy="0 0 0" xyz="0 0 0"/>
      <geometry>
        <mesh filename="package://robot_irb1660_id/meshes/link_5_bin_zeroed.stl"/>
      </geometry>
      <material name="abb_orange"/>
    </visual>
    <collision>
      <origin rpy="0 0 0" xyz="0 0 0"/>
      <geometry>
        <mesh filename="package://robot_irb1660_id/meshes/link_5_bin_zeroed.stl"/>
      </geometry>
      <material name="yellow"/>
    </collision>
  </link>
  <link name="link_6">
    <visual>
      <origin rpy="0 0 0" xyz="0 0 0"/>
      <geometry>
        <mesh filename="package://robot_irb1660_id/meshes/link_6_bin_zeroed.stl"/>
      </geometry>
      <material name="abb_orange"/>
    </visual>
    <collision>
      <origin rpy="0 0 0" xyz="0 0 0"/>
      <geometry>
        <mesh filename="package://robot_irb1660_id/meshes/link_6_bin_zeroed.stl"/>
      </geometry>
      <material name="yellow"/>
    </collision>
  </link>
  <link name="tool0"/>

  <!-- camera link list -->

  <link name="camera_link">
  <visual>
    <origin rpy="0 0 0" xyz="0 0 0"/>
    <geometry>
      <box size="0.2 0.2 0.2"/>
    </geometry>
    </visual>
    <material name="Cyan">
      <color rgba="0 1.0 1.0 1.0"/>
    </material>
  </link>
  <link name="camera_optical_frame"/>

  <!-- end of link list -->

  <!-- robot joint list -->
 
  <joint name="joint_1" type="revolute">
    <origin rpy="0 0 0" xyz="0 0 0.124"/>
    <parent link="base_link"/>
    <child link="link_1"/>
    <axis xyz="0 0 1"/>
    <limit effort="0" lower="-3.14159" upper="3.14159" velocity="3.14159"/>
  </joint>
  <joint name="joint_2" type="revolute">
    <origin rpy="0 0 0" xyz="0.15 -0.107 0.3625"/>
    <parent link="link_1"/>
    <child link="link_2"/>
    <axis xyz="0 1 0"/>
    <limit effort="0" lower="-1.5708" upper="2.61799" velocity="3.14159"/>
  </joint>
  <joint name="joint_3" type="revolute">
    <origin rpy="0 0 0" xyz="0 0 0.7"/>
    <parent link="link_2"/>
    <child link="link_3"/>
    <axis xyz="0 1 0"/>
    <limit effort="0" lower="-4.15388" upper="1.37881" velocity="3.14159"/>
  </joint>
  <joint name="joint_4" type="revolute">
    <origin rpy="0 0 0" xyz="0.128 0.107 0.108"/>
    <parent link="link_3"/>
    <child link="link_4"/>
    <axis xyz="1 0 0"/>
    <limit effort="0" lower="-3.05433" upper="3.05433" velocity="5.58505"/>
  </joint>
  <joint name="joint_5" type="revolute">
    <origin rpy="0 0 0" xyz="0.55 0 0"/>
    <parent link="link_4"/>
    <child link="link_5"/>
    <axis xyz="0 1 0"/>
    <limit effort="0" lower="-2.0944" upper="2.0944" velocity="6.28319"/>
  </joint>
  <joint name="joint_6" type="revolute">
    <origin rpy="0.0 0 0" xyz="0.135 0 0"/>
    <parent link="link_5"/>
    <child link="link_6"/>
    <axis xyz="1 0 0"/>
    <limit effort="0" lower="-6.98132" upper="6.98132" velocity="8.72665"/>
  </joint>
  <joint name="joint_6-tool0" type="fixed">
    <parent link="link_6"/>
    <child link="tool0"/>
    <origin rpy="0 0 0" xyz="0 0 0"/>
  </joint>
  
  <!-- camera joint list -->
  <joint name="camera_joint" type="fixed">
    <origin rpy="0 -3.14159 0" xyz="3.5 -1.10 -0.35" />
    <parent link="base_link" />
    <child link="camera_link" />
  </joint>
  <joint name="camera_optical_joint" type="fixed">
    <origin rpy="0 0 0" xyz="0 0 0" />
    <parent link="camera_link" />
    <child link="camera_optical_frame" />
  </joint>

  <!-- end of joint list -->
</robot>

